Workbook

Sheet Input
C2: Nama : | D2: ='DISC Test'!K2 -> Dewi | I2: Jenis kelamin : | K2: ='DISC Test'!K4 -> perempuan
C3: Usia : | D3: ='DISC Test'!K3 -> 37 Tahun | E3: tahun | I3: Tanggal Test : | K3: ='DISC Test'!K5
C5: P | D5: K | E5: P | F5: K | H5: P | I5: K | J5: P | K5: K | M5: P | N5: K | O5: P | P5: K
B6: 1 | C6: 2 | D6: 1 | E6: =IF(C6=1,"S",(IF(C6=2,"I",(IF(C6=3,"*",(IF(C6=4,"C","*"))))))) -> I | F6: =IF(D6=1,"S",(IF(D6=2,"I",(IF(D6=3,"D",(IF(D6=4,"C","*"))))))) -> S | G6: 9 | H6: ='DISC Test'!O12 -> 3 | I6: ='DISC Test'!Q12 -> 1 | J6: =IF(H6=1,"D",(IF(H6=2,"C",(IF(H6=3,"*",(IF(H6=4,"*","*"))))))) -> * | K6: =IF(I6=1,"D",(IF(I6=2,"C",(IF(I6=3,"I",(IF(I6=4,"S","*"))))))) -> D | L6: 17 | M6: ='DISC Test'!V12 -> 4 | N6: ='DISC Test'!X12 -> 3 | O6: =IF(M6=1,"*",(IF(M6=2,"D",(IF(M6=3,"S",(IF(M6=4,"I","*"))))))) -> I | P6: =IF(N6=1,"C",(IF(N6=2,"D",(IF(N6=3,"S",(IF(N6=4,"*","*"))))))) -> S
B7: 2 | C7: ='DISC Test'!H18 -> 3 | D7: ='DISC Test'!J18 -> 1 | E7: =IF(C7=1,"C",(IF(C7=2,"D",(IF(C7=3,"*",(IF(C7=4,"S","*"))))))) -> * | F7: =IF(D7=1,"*",(IF(D7=2,"D",(IF(D7=3,"I",(IF(D7=4,"S","*"))))))) -> * | G7: 10 | H7: ='DISC Test'!O18 -> 4 | I7: ='DISC Test'!Q18 -> 3 | J7: =IF(H7=1,"*",(IF(H7=2,"D",(IF(H7=3,"S",(IF(H7=4,"I","*"))))))) -> I | K7: =IF(I7=1,"C",(IF(I7=2,"D",(IF(I7=3,"S",(IF(I7=4,"*","*"))))))) -> S | L7: 18 | M7: ='DISC Test'!V18 -> 1 | N7: ='DISC Test'!X18 -> 4 | O7: =IF(M7=1,"D",(IF(M7=2,"*",(IF(M7=3,"*",(IF(M7=4,"C","*"))))))) -> D | P7: =IF(N7=1,"D",(IF(N7=2,"I",(IF(N7=3,"S",(IF(N7=4,"*","*"))))))) -> *
B8: 3 | C8: ='DISC Test'!H24 -> 1 | D8: ='DISC Test'!J24 -> 3 | E8: =IF(C8=1,"I",(IF(C8=2,"*",(IF(C8=3,"*",(IF(C8=4,"D","*"))))))) -> I | F8: =IF(D8=1,"I",(IF(D8=2,"C",(IF(D8=3,"S",(IF(D8=4,"*","*"))))))) -> S | G8: 11 | H8: ='DISC Test'!O24 -> 1 | I8: ='DISC Test'!Q24 -> 4 | J8: =IF(H8=1,"S",(IF(H8=2,"*",(IF(H8=3,"D",(IF(H8=4,"C","*"))))))) -> S | K8: =IF(I8=1,"*",(IF(I8=2,"I",(IF(I8=3,"D",(IF(I8=4,"C","*"))))))) -> C | L8: 19 | M8: ='DISC Test'!V24 -> 1 | N8: ='DISC Test'!X24 -> 4 | O8: =IF(M8=1,"D",(IF(M8=2,"S",(IF(M8=3,"I",(IF(M8=4,"*","*"))))))) -> D | P8: =IF(N8=1,"D",(IF(N8=2,"*",(IF(N8=3,"I",(IF(N8=4,"C","*"))))))) -> C
B9: 4 | C9: ='DISC Test'!H30 -> 3 | D9: ='DISC Test'!J30 -> 1 | E9: =IF(C9=1,"C",(IF(C9=2,"S",(IF(C9=3,"*",(IF(C9=4,"D","*"))))))) -> * | F9: =IF(D9=1,"C",(IF(D9=2,"S",(IF(D9=3,"I",(IF(D9=4,"D","*"))))))) -> C | G9: 12 | H9: ='DISC Test'!O30 -> 4 | I9: ='DISC Test'!Q30 -> 1 | J9: =IF(H9=1,"*",(IF(H9=2,"C",(IF(H9=3,"I",(IF(H9=4,"D","*"))))))) -> D | K9: =IF(I9=1,"S",(IF(I9=2,"*",(IF(I9=3,"I",(IF(I9=4,"D","*"))))))) -> S | L9: 20 | M9: ='DISC Test'!V30 -> 1 | N9: ='DISC Test'!X30 -> 4 | O9: =IF(M9=1,"D",(IF(M9=2,"S",(IF(M9=3,"I",(IF(M9=4,"C","*"))))))) -> D | P9: =IF(N9=1,"*",(IF(N9=2,"S",(IF(N9=3,"I",(IF(N9=4,"*","*"))))))) -> *
B10: 5 | C10: ='DISC Test'!H36 -> 1 | D10: ='DISC Test'!J36 -> 2 | E10: =IF(C10=1,"I",(IF(C10=2,"D",(IF(C10=3,"S",(IF(C10=4,"*","*"))))))) -> I | F10: =IF(D10=1,"*",(IF(D10=2,"D",(IF(D10=3,"S",(IF(D10=4,"C","*"))))))) -> D | G10: 13 | H10: ='DISC Test'!O36 -> 3 | I10: ='DISC Test'!Q36 -> 4 | J10: =IF(H10=1,"D",(IF(H10=2,"S",(IF(H10=3,"I",(IF(H10=4,"*","*"))))))) -> I | K10: =IF(I10=1,"D",(IF(I10=2,"*",(IF(I10=3,"*",(IF(I10=4,"C","*"))))))) -> C | L10: 21 | M10: ='DISC Test'!V36 -> 3 | N10: ='DISC Test'!X36 -> 4 | O10: =IF(M10=1,"S",(IF(M10=2,"D",(IF(M10=3,"I",(IF(M10=4,"*","*"))))))) -> I | P10: =IF(N10=1,"S",(IF(N10=2,"D",(IF(N10=3,"I",(IF(N10=4,"C","*"))))))) -> C
B11: 6 | C11: ='DISC Test'!H42 -> 2 | D11: ='DISC Test'!J42 -> 1 | E11: =IF(C11=1,"C",(IF(C11=2,"D",(IF(C11=3,"I",(IF(C11=4,"S","*"))))))) -> D | F11: =IF(D11=1,"*",(IF(D11=2,"D",(IF(D11=3,"I",(IF(D11=4,"S","*"))))))) -> * | G11: 14 | H11: ='DISC Test'!O42 -> 4 | I11: ='DISC Test'!Q42 -> 1 | J11: =IF(H11=1,"C",(IF(H11=2,"I",(IF(H11=3,"S",(IF(H11=4,"D","*"))))))) -> D | K11: =IF(I11=1,"C",(IF(I11=2,"I",(IF(I11=3,"*",(IF(I11=4,"D","*"))))))) -> C | L11: 22 | M11: ='DISC Test'!V42 -> 3 | N11: ='DISC Test'!X42 -> 4 | O11: =IF(M11=1,"S",(IF(M11=2,"*",(IF(M11=3,"D",(IF(M11=4,"C","*"))))))) -> D | P11: =IF(N11=1,"S",(IF(N11=2,"I",(IF(N11=3,"D",(IF(N11=4,"C","*"))))))) -> C
B12: 7 | C12: ='DISC Test'!H48 -> 2 | D12: ='DISC Test'!J48 -> 1 | E12: =IF(C12=1,"S",(IF(C12=2,"I",(IF(C12=3,"*",(IF(C12=4,"*","*"))))))) -> I | F12: =IF(D12=1,"*",(IF(D12=2,"I",(IF(D12=3,"C",(IF(D12=4,"D","*"))))))) -> * | G12: 15 | H12: ='DISC Test'!O48 -> 2 | I12: ='DISC Test'!Q48 -> 4 | J12: =IF(H12=1,"S",(IF(H12=2,"C",(IF(H12=3,"I",(IF(H12=4,"D","*"))))))) -> C | K12: =IF(I12=1,"S",(IF(I12=2,"*",(IF(I12=3,"I",(IF(I12=4,"D","*"))))))) -> D | L12: 23 | M12: ='DISC Test'!V48 -> 2 | N12: ='DISC Test'!X48 -> 3 | O12: =IF(M12=1,"*",(IF(M12=2,"I",(IF(M12=3,"S",(IF(M12=4,"*","*"))))))) -> I | P12: =IF(N12=1,"D",(IF(N12=2,"*",(IF(N12=3,"S",(IF(N12=4,"C","*"))))))) -> S
B13: 8 | C13: ='DISC Test'!H54 -> 1 | D13: ='DISC Test'!J54 -> 2 | E13: =IF(C13=1,"I",(IF(C13=2,"S",(IF(C13=3,"C",(IF(C13=4,"D","*"))))))) -> I | F13: =IF(D13=1,"I",(IF(D13=2,"S",(IF(D13=3,"C",(IF(D13=4,"D","*"))))))) -> S | G13: 16 | H13: ='DISC Test'!O54 -> 2 | I13: ='DISC Test'!Q54 -> 1 | J13: =IF(H13=1,"*",(IF(H13=2,"C",(IF(H13=3,"I",(IF(H13=4,"S","*"))))))) -> C | K13: =IF(I13=1,"D",(IF(I13=2,"*",(IF(I13=3,"I",(IF(I13=4,"S","*"))))))) -> D | L13: 24 | M13: ='DISC Test'!V54 -> 1 | N13: ='DISC Test'!X54 -> 4 | O13: =IF(M13=1,"*",(IF(M13=2,"I",(IF(M13=3,"D",(IF(M13=4,"C","*"))))))) -> * | P13: =IF(N13=1,"S",(IF(N13=2,"I",(IF(N13=3,"*",(IF(N13=4,"*","*"))))))) -> *
C15: HASIL | D15: D | E15: =COUNTIF($E$6:$E$13,"D") -> 1 | F15: =COUNTIF($F$6:$F$13,"D") -> 1 | I15: D | J15: =COUNTIF($J$6:$J$13,"D") -> 2 | K15: =COUNTIF($K$6:$K$13,"D") -> 3 | N15: D | O15: =COUNTIF($O$6:$O$13,"D") -> 4 | P15: =COUNTIF($P$6:$P$13,"D") -> 0
D16: I | E16: =COUNTIF($E$6:$E$13,"I") -> 5 | F16: =COUNTIF($F$6:$F$13,"I") -> 0 | I16: I | J16: =COUNTIF($J$6:$J$13,"I") -> 2 | K16: =COUNTIF($K$6:$K$13,"I") -> 0 | N16: I | O16: =COUNTIF($O$6:$O$13,"I") -> 3 | P16: =COUNTIF($P$6:$P$13,"I") -> 0
D17: S | E17: =COUNTIF($E$6:$E$13,"S") -> 0 | F17: =COUNTIF($F$6:$F$13,"S") -> 3 | I17: S | J17: =COUNTIF($J$6:$J$13,"S") -> 1 | K17: =COUNTIF($K$6:$K$13,"S") -> 2 | N17: S | O17: =COUNTIF($O$6:$O$13,"S") -> 0 | P17: =COUNTIF($P$6:$P$13,"S") -> 2
D18: C | E18: =COUNTIF($E$6:$E$13,"C") -> 0 | F18: =COUNTIF($F$6:$F$13,"C") -> 1 | I18: C | J18: =COUNTIF($J$6:$J$13,"C") -> 2 | K18: =COUNTIF($K$6:$K$13,"C") -> 3 | N18: C | O18: =COUNTIF($O$6:$O$13,"C") -> 0 | P18: =COUNTIF($P$6:$P$13,"C") -> 3
D19: * | E19: =8-(SUM(E15:E18)) -> 2 | F19: =8-(SUM(F15:F18)) -> 3 | I19: * | J19: =8-(SUM(J15:J18)) -> 1 | K19: =8-(SUM(K15:K18)) -> 0 | N19: * | O19: =8-(SUM(O15:O18)) -> 1 | P19: =8-(SUM(P15:P18)) -> 3

Sheet DISC Test
F1: D.I.S.C. Test
F2: Nama | K2: Dewi | M2: INSTRUKSI : Terdapat 24 soal, Setiap nomor di bawah ini memuat 4 (empat) kalimat. Tugas anda adalah : 1. Beri tanda [x] pada kolom di bawah huruf [P] di samping kalimat yang PALING menggambarkan diri anda 2. Beri tanda [x] pada kolom di bawah huruf [K] di samping kalimat yang PALING TIDAK menggambarkan diri anda PERHATIKAN : Setiap nomor hanya ada 1 (satu) tanda [x] di bawah masing-masing kolom P dan K.
F3: Usia | K3: 37 Tahun
F4: Jenis Kelamin | K4: perempuan
F5: Tanggal Tes
F7: No. | G7: P | I7: K | K7: Gambaran Diri | M7: No. | N7: P | P7: K | R7: Gambaran Diri | T7: No. | U7: P | W7: K | Y7: Gambaran Diri
F8: 1 | H8: =IF(G8="",0,1) -> 0 | J8: =IF(I8="",0,1) -> 0 | K8: Gampangan, Mudah setuju | M8: 9 | O8: =IF(N8="",0,1) -> 0 | P8: x | Q8: =IF(P8="",0,1) -> 1 | R8: Hasil adalah penting | T8: 17 | V8: =IF(U8="",0,1) -> 0 | X8: =IF(W8="",0,1) -> 0 | Y8: Pendidikan, Kebudayaan
G9: x | H9: =IF(G9="",0,2) -> 2 | J9: =IF(I9="",0,2) -> 0 | K9: Percaya, Mudah percaya pada orang | O9: =IF(N9="",0,2) -> 0 | Q9: =IF(P9="",0,2) -> 0 | R9: Lakukan dengan benar, Akurasi penting | V9: =IF(U9="",0,2) -> 0 | X9: =IF(W9="",0,2) -> 0 | Y9: Prestasi, Ganjaran
H10: =IF(G10="",0,3) -> 0 | I10: x | J10: =IF(I10="",0,3) -> 3 | K10: Petualang, Mengambil resiko | N10: x | O10: =IF(N10="",0,3) -> 3 | Q10: =IF(P10="",0,3) -> 0 | R10: Dibuat menyenangkan | V10: =IF(U10="",0,3) -> 0 | W10: X | X10: =IF(W10="",0,3) -> 3 | Y10: Keselamatan, keamanan
H11: =IF(G11="",0,4) -> 0 | J11: =IF(I11="",0,4) -> 0 | K11: Toleran, Menghormati | O11: =IF(N11="",0,4) -> 0 | Q11: =IF(P11="",0,4) -> 0 | R11: Mari kerjakan bersama | U11: X | V11: =IF(U11="",0,4) -> 4 | X11: =IF(W11="",0,4) -> 0 | Y11: Sosial, Perkumpulan kelompok
G12: =(COUNTIF(G8:G11,"x")) -> 1 | H12: =SUM(H8:H11) -> 2 | I12: =(COUNTIF(I8:I11,"x")) -> 1 | J12: =SUM(J8:J11) -> 3 | N12: =(COUNTIF(N8:N11,"x")) -> 1 | O12: =SUM(O8:O11) -> 3 | P12: =(COUNTIF(P8:P11,"x")) -> 1 | Q12: =SUM(Q8:Q11) -> 1 | U12: =(COUNTIF(U8:U11,"x")) -> 1 | V12: =SUM(V8:V11) -> 4 | W12: =(COUNTIF(W8:W11,"x")) -> 1 | X12: =SUM(X8:X11) -> 3 | AA12: =SUM(G12,I12,N12,P12,U12,W12) -> 6
F13: No. | G13: P | I13: K | K13: Gambaran Diri | M13: No. | N13: P | P13: K | R13: Gambaran Diri | T13: No. | U13: P | W13: K | Y13: Gambaran Diri
F14: 2 | H14: =IF(G14="",0,1) -> 0 | I14: x | J14: =IF(I14="",0,1) -> 1 | K14: Lembut suara, Pendiam | M14: =M8+1 -> 10 | O14: =IF(N14="",0,1) -> 0 | Q14: =IF(P14="",0,1) -> 0 | R14: Akan berjalan terus tanpa kontrol diri | T14: =T8+1 -> 18 | U14: X | V14: =IF(U14="",0,1) -> 1 | X14: =IF(W14="",0,1) -> 0 | Y14: Memimpin, Pendekatan langsung
H15: =IF(G15="",0,2) -> 0 | J15: =IF(I15="",0,2) -> 0 | K15: Optimistik, Visioner | O15: =IF(N15="",0,2) -> 0 | Q15: =IF(P15="",0,2) -> 0 | R15: Akan membeli sesuai dorongan hati | V15: =IF(U15="",0,2) -> 0 | X15: =IF(W15="",0,2) -> 0 | Y15: Suka bergaul, Antusias
G16: x | H16: =IF(G16="",0,3) -> 3 | J16: =IF(I16="",0,3) -> 0 | K16: Pusat Perhatian, Suka gaul | O16: =IF(N16="",0,3) -> 0 | P16: x | Q16: =IF(P16="",0,3) -> 3 | R16: Akan menunggu, Tanpa tekanan | V16: =IF(U16="",0,3) -> 0 | X16: =IF(W16="",0,3) -> 0 | Y16: Dapat diramal, Konsisten
H17: =IF(G17="",0,4) -> 0 | J17: =IF(I17="",0,4) -> 0 | K17: Pendamai, Membawa Harmoni | N17: x | O17: =IF(N17="",0,4) -> 4 | Q17: =IF(P17="",0,4) -> 0 | R17: Akan mengusahakan yang kuinginkan | V17: =IF(U17="",0,4) -> 0 | W17: X | X17: =IF(W17="",0,4) -> 4 | Y17: Waspada, Hati-hati
G18: =(COUNTIF(G14:G17,"x")) -> 1 | H18: =SUM(H14:H17) -> 3 | I18: =(COUNTIF(I14:I17,"x")) -> 1 | J18: =SUM(J14:J17) -> 1 | N18: =(COUNTIF(N14:N17,"x")) -> 1 | O18: =SUM(O14:O17) -> 4 | P18: =(COUNTIF(P14:P17,"x")) -> 1 | Q18: =SUM(Q14:Q17) -> 3 | U18: =(COUNTIF(U14:U17,"x")) -> 1 | V18: =SUM(V14:V17) -> 1 | W18: =(COUNTIF(W14:W17,"x")) -> 1 | X18: =SUM(X14:X17) -> 4 | AA18: =SUM(G18,I18,N18,P18,U18,W18) -> 6
F19: No. | G19: P | I19: K | K19: Gambaran Diri | M19: No. | N19: P | P19: K | R19: Gambaran Diri | T19: No. | U19: P | W19: K | Y19: Gambaran Diri
F20: 3 | G20: x | H20: =IF(G20="",0,1) -> 1 | J20: =IF(I20="",0,1) -> 0 | K20: Menyemangati orang | M20: =M14+1 -> 11 | N20: x | O20: =IF(N20="",0,1) -> 1 | Q20: =IF(P20="",0,1) -> 0 | R20: Ramah, Mudah bergabung | T20: =T14+1 -> 19 | U20: X | V20: =IF(U20="",0,1) -> 1 | X20: =IF(W20="",0,1) -> 0 | Y20: Tidak mudah dikalahkan
H21: =IF(G21="",0,2) -> 0 | J21: =IF(I21="",0,2) -> 0 | K21: Berusaha sempurna | O21: =IF(N21="",0,2) -> 0 | Q21: =IF(P21="",0,2) -> 0 | R21: Unik, Bosan rutinitas | V21: =IF(U21="",0,2) -> 0 | X21: =IF(W21="",0,2) -> 0 | Y21: Kerjakan sesuai perintah, Ikut pimpinan
H22: =IF(G22="",0,3) -> 0 | I22: x | J22: =IF(I22="",0,3) -> 3 | K22: Bagian dari kelompok | O22: =IF(N22="",0,3) -> 0 | Q22: =IF(P22="",0,3) -> 0 | R22: Aktif mengubah sesuatu | V22: =IF(U22="",0,3) -> 0 | X22: =IF(W22="",0,3) -> 0 | Y22: Mudah terangsang, Riang
H23: =IF(G23="",0,4) -> 0 | J23: =IF(I23="",0,4) -> 0 | K23: Ingin membuat tujuan | O23: =IF(N23="",0,4) -> 0 | P23: x | Q23: =IF(P23="",0,4) -> 4 | R23: Ingin hal-hal yang pasti | V23: =IF(U23="",0,4) -> 0 | W23: X | X23: =IF(W23="",0,4) -> 4 | Y23: Ingin segalanya teratur, Rapi
G24: =(COUNTIF(G20:G23,"x")) -> 1 | H24: =SUM(H20:H23) -> 1 | I24: =(COUNTIF(I20:I23,"x")) -> 1 | J24: =SUM(J20:J23) -> 3 | N24: =(COUNTIF(N20:N23,"x")) -> 1 | O24: =SUM(O20:O23) -> 1 | P24: =(COUNTIF(P20:P23,"x")) -> 1 | Q24: =SUM(Q20:Q23) -> 4 | U24: =(COUNTIF(U20:U23,"x")) -> 1 | V24: =SUM(V20:V23) -> 1 | W24: =(COUNTIF(W20:W23,"x")) -> 1 | X24: =SUM(X20:X23) -> 4 | AA24: =SUM(G24,I24,N24,P24,U24,W24) -> 6
F25: No. | G25: P | I25: K | K25: Gambaran Diri | M25: No. | N25: P | P25: K | R25: Gambaran Diri | T25: No. | U25: P | W25: K | Y25: Gambaran Diri
F26: =F20+1 -> 4 | H26: =IF(G26="",0,1) -> 0 | I26: x | J26: =IF(I26="",0,1) -> 1 | K26: Menjadi frustrasi | M26: =M20+1 -> 12 | O26: =IF(N26="",0,1) -> 0 | P26: x | Q26: =IF(P26="",0,1) -> 1 | R26: Non-konfrontasi, Menyerah | T26: =T20+1 -> 20 | U26: X | V26: =IF(U26="",0,1) -> 1 | X26: =IF(W26="",0,1) -> 0 | Y26: Saya akan pimpin mereka
H27: =IF(G27="",0,2) -> 0 | J27: =IF(I27="",0,2) -> 0 | K27: Menyimpan perasaan saya | O27: =IF(N27="",0,2) -> 0 | Q27: =IF(P27="",0,2) -> 0 | R27: Dipenuhi hal detail | V27: =IF(U27="",0,2) -> 0 | X27: =IF(W27="",0,2) -> 0 | Y27: Saya akan melaksanakan
G28: x | H28: =IF(G28="",0,3) -> 3 | J28: =IF(I28="",0,3) -> 0 | K28: Menceritakan sisi saya | O28: =IF(N28="",0,3) -> 0 | Q28: =IF(P28="",0,3) -> 0 | R28: Perubahan pada menit terakhir | V28: =IF(U28="",0,3) -> 0 | X28: =IF(W28="",0,3) -> 0 | Y28: Saya akan meyakinkan mereka
H29: =IF(G29="",0,4) -> 0 | J29: =IF(I29="",0,4) -> 0 | K29: Siap beroposisi | N29: x | O29: =IF(N29="",0,4) -> 4 | Q29: =IF(P29="",0,4) -> 0 | R29: Menuntut, Kasar | V29: =IF(U29="",0,4) -> 0 | W29: X | X29: =IF(W29="",0,4) -> 4 | Y29: Saya dapatkan fakta
G30: =(COUNTIF(G26:G29,"x")) -> 1 | H30: =SUM(H26:H29) -> 3 | I30: =(COUNTIF(I26:I29,"x")) -> 1 | J30: =SUM(J26:J29) -> 1 | N30: =(COUNTIF(N26:N29,"x")) -> 1 | O30: =SUM(O26:O29) -> 4 | P30: =(COUNTIF(P26:P29,"x")) -> 1 | Q30: =SUM(Q26:Q29) -> 1 | U30: =(COUNTIF(U26:U29,"x")) -> 1 | V30: =SUM(V26:V29) -> 1 | W30: =(COUNTIF(W26:W29,"x")) -> 1 | X30: =SUM(X26:X29) -> 4 | AA30: =SUM(G30,I30,N30,P30,U30,W30) -> 6
F31: No. | G31: P | I31: K | K31: Gambaran Diri | M31: No. | N31: P | P31: K | R31: Gambaran Diri | T31: No. | U31: P | W31: K | Y31: Gambaran Diri
F32: =F26+1 -> 5 | G32: x | H32: =IF(G32="",0,1) -> 1 | J32: =IF(I32="",0,1) -> 0 | K32: Hidup, Suka bicara | M32: =M26+1 -> 13 | O32: =IF(N32="",0,1) -> 0 | Q32: =IF(P32="",0,1) -> 0 | R32: Ingin kemajuan | T32: =T26+1 -> 21 | V32: =IF(U32="",0,1) -> 0 | X32: =IF(W32="",0,1) -> 0 | Y32: Memikirkan orang dahulu
H33: =IF(G33="",0,2) -> 0 | I33: x | J33: =IF(I33="",0,2) -> 2 | K33: Gerak cepat, Tekun | O33: =IF(N33="",0,2) -> 0 | Q33: =IF(P33="",0,2) -> 0 | R33: Puas dengan segalanya | V33: =IF(U33="",0,2) -> 0 | X33: =IF(W33="",0,2) -> 0 | Y33: Kompetitif, Suka tantangan
H34: =IF(G34="",0,3) -> 0 | J34: =IF(I34="",0,3) -> 0 | K34: Usaha menjaga keseimbangan | N34: x | O34: =IF(N34="",0,3) -> 3 | Q34: =IF(P34="",0,3) -> 0 | R34: Terbuka memperlihatkan perasaan | U34: x | V34: =IF(U34="",0,3) -> 3 | X34: =IF(W34="",0,3) -> 0 | Y34: Optimis, Positif
H35: =IF(G35="",0,4) -> 0 | J35: =IF(I35="",0,4) -> 0 | K35: Usaha mengikuti aturan | O35: =IF(N35="",0,4) -> 0 | P35: X | Q35: =IF(P35="",0,4) -> 4 | R35: Rendah hati, Sederhana | V35: =IF(U35="",0,4) -> 0 | W35: x | X35: =IF(W35="",0,4) -> 4 | Y35: Pemikir logis, Sistematik
G36: =(COUNTIF(G32:G35,"x")) -> 1 | H36: =SUM(H32:H35) -> 1 | I36: =(COUNTIF(I32:I35,"x")) -> 1 | J36: =SUM(J32:J35) -> 2 | N36: =(COUNTIF(N32:N35,"x")) -> 1 | O36: =SUM(O32:O35) -> 3 | P36: =(COUNTIF(P32:P35,"x")) -> 1 | Q36: =SUM(Q32:Q35) -> 4 | U36: =(COUNTIF(U32:U35,"x")) -> 1 | V36: =SUM(V32:V35) -> 3 | W36: =(COUNTIF(W32:W35,"x")) -> 1 | X36: =SUM(X32:X35) -> 4 | AA36: =SUM(G36,I36,N36,P36,U36,W36) -> 6
F37: No. | G37: P | I37: K | K37: Gambaran Diri | M37: No. | N37: P | P37: K | R37: Gambaran Diri | T37: No. | U37: P | W37: K | Y37: Gambaran Diri
F38: =F32+1 -> 6 | H38: =IF(G38="",0,1) -> 0 | I38: x | J38: =IF(I38="",0,1) -> 1 | K38: Kelola waktu secara efisien | M38: =M32+1 -> 14 | O38: =IF(N38="",0,1) -> 0 | P38: x | Q38: =IF(P38="",0,1) -> 1 | R38: Tenang, Pendiam | T38: =T32+1 -> 22 | V38: =IF(U38="",0,1) -> 0 | X38: =IF(W38="",0,1) -> 0 | Y38: Menyenangkan orang, Mudah setuju
G39: x | H39: =IF(G39="",0,2) -> 2 | J39: =IF(I39="",0,2) -> 0 | K39: Sering terburu-buru, Merasa tertekan | O39: =IF(N39="",0,2) -> 0 | Q39: =IF(P39="",0,2) -> 0 | R39: Bahagia, Tanpa beban | V39: =IF(U39="",0,2) -> 0 | X39: =IF(W39="",0,2) -> 0 | Y39: Tertawa lepas, Hidup
H40: =IF(G40="",0,3) -> 0 | J40: =IF(I40="",0,3) -> 0 | K40: Masalah sosial itu penting | O40: =IF(N40="",0,3) -> 0 | Q40: =IF(P40="",0,3) -> 0 | R40: Menyenangkan, Baik hati | U40: x | V40: =IF(U40="",0,3) -> 3 | X40: =IF(W40="",0,3) -> 0 | Y40: Berani, Tak gentar
H41: =IF(G41="",0,4) -> 0 | J41: =IF(I41="",0,4) -> 0 | K41: Suka selesaikan apa yang saya mulai | N41: x | O41: =IF(N41="",0,4) -> 4 | Q41: =IF(P41="",0,4) -> 0 | R41: Tak gentar, Berani | V41: =IF(U41="",0,4) -> 0 | W41: x | X41: =IF(W41="",0,4) -> 4 | Y41: Tenang, Pendiam
...

Sheet Psikogram
A1: D I S C
A2: Personality System Graph Page
G4: Name | H4: : | I4: =Input!D2 -> Dewi | BH4: 1 | BI4: 2 | BJ4: 3 | BK4: 4 | BL4: 5 | BM4: 6 | BN4: 7 | BO4: 8 | BP4: 9 | BQ4: 10 | BR4: 11 | BS4: 12 | BT4: 13 | BU4: 14 | BV4: 15 | BW4: 16 | BX4: 17 | BY4: 18 | BZ4: 19 | CA4: 20 | CB4: 21 | CC4: 22 | CD4: 23 | CE4: 24 | CF4: 25 | CG4: 26 | CH4: 27 | CI4: 28 | CJ4: 29 | CK4: 30 | CL4: 31 | CM4: 32 | CN4: 33 | CO4: 34 | CP4: 35 | CQ4: 36 | CR4: 37 | CS4: 38 | CT4: 39 | CU4: 40
G5: Age | H5: : | I5: =Input!D3 -> 37 Tahun | BH5: C | BI5: D | BJ5: C-D | BK5: I-D | BL5: I-D-C | BM5: I-D-S | BN5: I-S-D | BO5: S-D-C | BP5: D-I | BQ5: D-I-S | BR5: D-S | BS5: C-I-S | BT5: C-S-I | BU5: I-S-C / I-C-S | BV5: S | BW5: C-S | BX5: S-C | BY5: D-C | BZ5: D-I-C | CA5: D-S-I | CB5: D-S-C | CC5: D-C-I | CD5: D-C-S | CE5: I | CF5: I-S | CG5: I-C | CH5: I-C-D | CI5: I-C-S | CJ5: S-D | CK5: S-I | CL5: S-D-I | CM5: S-I-D | CN5: S-I-C | CO5: S-C-D | CP5: S-C-I | CQ5: C-I | CR5: C-D-I | CS5: C-D-S | CT5: C-I-D | CU5: C-S-D
G6: Gender | H6: : | I6: =Input!K2 -> perempuan | BA6: Line | BB6: D | BC6: I | BD6: S | BE6: C
G7: Tgl. Tes | H7: : | I7: =Input!K3 | BA7: 1 | BB7: =VLOOKUP(H10,Sheet3!$B$3:$F$23,2) -> 0.5 | BC7: =VLOOKUP(I10,Sheet3!$B$3:$F$23,3) -> 6.5 | BD7: =VLOOKUP(J10,Sheet3!$B$3:$F$23,4) -> -4.3 | BE7: =VLOOKUP(K10,Sheet3!$B$3:$F$23,5) -> -3.5 | BH7: =IF(AND(BB7<=0,BC7<=0,BD7<=0,BE7>0)=TRUE,1,0) -> 0 | BI7: =IF(AND(BB7>0,BC7<=0,BD7<=0,BE7<=0)=TRUE,1,0) -> 0 | BJ7: =IF(AND(BB7>0,BC7<=0,BD7<=0,BE7>0,BE7>=BB7)=TRUE,1,0) -> 0 | BK7: =IF(AND(BB7>0,BC7>0,BD7<=0,BE7<=0,BC7>=BB7)=TRUE,1,0) -> 1 | BL7: =IF(AND(BB7>0,BC7>0,BD7<=0,BE7>0,BC7>=BB7,BB7>=BE7)=TRUE,1,0) -> 0 | BM7: =IF(AND(BB7>0,BC7>0,BD7>0,BE7<=0,BC7>=BB7,BB7>=BD7)=TRUE,1,0) -> 0 | BN7: =IF(AND(BB7>0,BC7>0,BD7>0,BE7<=0,BC7>=BD7,BD7>=BB7)=TRUE,1,0) -> 0 | BO7: =IF(AND(BB7>0,BC7<=0,BD7>0,BE7>0,BD7>=BB7,BB7>=BE7)=TRUE,1,0) -> 0 | BP7: =IF(AND(BB7>0,BC7>0,BD7<=0,BE7<=0,BB7>=BC7)=TRUE,1,0) -> 0 | BQ7: =IF(AND(BB7>0,BC7>0,BD7>0,BE7<=0,BB7>=BC7,BC7>=BD7)=TRUE,1,0) -> 0 | BR7: =IF(AND(BB7>0,BC7<=0,BD7>0,BE7<=0,BB7>=BD7)=TRUE,1,0) -> 0 | BS7: =IF(AND(BB7<=0,BC7>0,BD7>0,BE7>0,BE7>=BC7,BC7>=BD7)=TRUE,1,0) -> 0 | BT7: =IF(AND(BB7<=0,BC7>0,BD7>0,BE7>0,BE7>=BD7,BD7>=BC7)=TRUE,1,0) -> 0 | BU7: =IF(AND(BB7<=0,BC7>0,BD7>0,BE7>0,BC7>=BD7,BC7>=BE7)=TRUE,1,0) -> 0 | BV7: =IF(AND(BB7<=0,BC7<=0,BD7>0,BE7<=0)=TRUE,1,0) -> 0 | BW7: =IF(AND(BB7<=0,BC7<=0,BD7>0,BE7>0,BE7>=BD7)=TRUE,1,0) -> 0 | BX7: =IF(AND(BB7<=0,BC7<=0,BD7>0,BE7>0,BD7>=BE7)=TRUE,1,0) -> 0 | BY7: =IF(AND(BC7<=0,BD7<=0,BB7>0,BE7>0,BB7>=BE7)=TRUE,1,0) -> 0 | BZ7: =IF(AND(BB7>0,BC7>0,BE7>0,BD7<=0,BB7>=BC7,BC7>=BE7)=TRUE,1,0) -> 0 | CA7: =IF(AND(BB7>0,BD7>0,BC7>0,BE7<=0,BB7>=BD7,BD7>=BC7)=TRUE,1,0) -> 0 | CB7: =IF(AND(BB7>0,BD7>0,BE7>0,BC7<=0,BB7>=BD7,BD7>=BE7)=TRUE,1,0) -> 0 | CC7: =IF(AND(BB7>0,BC7>0,BE7>0,BD7<=0,BB7>=BE7,BE7>=BC7)=TRUE,1,0) -> 0 | CD7: =IF(AND(BB7>0,BD7>0,BE7>0,BC7<=0,BB7>=BE7,BE7>=BD7)=TRUE,1,0) -> 0 | CE7: =IF(AND(BB7<=0,BD7<=0,BE7<=0,BC7>0)=TRUE,1,0) -> 0 | CF7: =IF(AND(BC7>0,BD7>0,BB7<=0,BE7<=0,BC7>=BD7)=TRUE,1,0) -> 0 | CG7: =IF(AND(BC7>0,BE7>0,BB7<=0,BD7<=0,BC7>=BE7)=TRUE,1,0) -> 0 | CH7: =IF(AND(BB7>0,BC7>0,BE7>0,BD7<=0,BC7>=BE7,BE7>=BB7)=TRUE,1,0) -> 0 | CI7: =IF(AND(BB7<=0,BC7>0,BD7>0,BE7>0,BC7>=BE7,BE7>=BD7)=TRUE,1,0) -> 0 | CJ7: =IF(AND(BB7>0,BC7<=0,BD7>0,BE7<=0,BD7>=BB7)=TRUE,1,0) -> 0 | CK7: =IF(AND(BC7>0,BD7>0,BB7<=0,BE7<=0,BD7>=BC7)=TRUE,1,0) -> 0 | CL7: =IF(AND(BB7>0,BC7>0,BD7>0,BE7<=0,BD7>=BB7,BB7>=BC7)=TRUE,1,0) -> 0 | CM7: =IF(AND(BB7>0,BC7>0,BD7>0,BE7<=0,BD7>=BC7,BC7>=BB7)=TRUE,1,0) -> 0 | CN7: =IF(AND(BC7>0,BD7>0,BE7>0,BB7<=0,BD7>=BC7,BC7>=BE7)=TRUE,1,0) -> 0 | CO7: =IF(AND(BB7>0,BC7<=0,BD7>0,BE7>0,BD7>=BE7,BE7>=BB7)=TRUE,1,0) -> 0 | CP7: =IF(AND(BC7>0,BD7>0,BE7>0,BB7<=0,BD7>=BE7,BE7>=BC7)=TRUE,1,0) -> 0 | CQ7: =IF(AND(BC7>0,BE7>0,BB7<=0,BD7<=0,BE7>=BC7)=TRUE,1,0) -> 0 | CR7: =IF(AND(BB7>0,BC7>0,BE7>0,BD7<=0,BE7>=BB7,BB7>=BC7)=TRUE,1,0) -> 0 | CS7: =IF(AND(BB7>0,BD7>0,BE7>0,BC7<=0,BE7>=BB7,BB7>=BD7)=TRUE,1,0) -> 0 | CT7: =IF(AND(BB7>0,BC7>0,BE7>0,BD7<=0,BE7>=BC7,BC7>=BB7)=TRUE,1,0) -> 0 | CU7: =IF(AND(BB7>0,BD7>0,BE7>0,BC7<=0,BE7>=BD7,BD7>=BB7)=TRUE,1,0) -> 0 | CY7: =MATCH(1,BH7:CW7,0) -> 4
BB8: D | BC8: I | BD8: S | BE8: C
G9: Line | H9: D | I9: I | J9: S | K9: C | L9: * | M9: tot | BA9: 2 | BB9: =VLOOKUP(H11,Sheet3!$B$3:$N$23,6) -> 1.5 | BC9: =VLOOKUP(I11,Sheet3!$B$3:$N$23,7) -> 7 | BD9: =VLOOKUP(J11,Sheet3!$B$3:$N$23,8) -> -1.3 | BE9: =VLOOKUP(K11,Sheet3!$B$3:$N$23,9) -> 0 | BH9: =IF(AND(BB9<=0,BC9<=0,BD9<=0,BE9>0)=TRUE,1,0) -> 0 | BI9: =IF(AND(BB9>0,BC9<=0,BD9<=0,BE9<=0)=TRUE,1,0) -> 0 | BJ9: =IF(AND(BB9>0,BC9<=0,BD9<=0,BE9>0,BE9>=BB9)=TRUE,1,0) -> 0 | BK9: =IF(AND(BB9>0,BC9>0,BD9<=0,BE9<=0,BC9>=BB9)=TRUE,1,0) -> 1 | BL9: =IF(AND(BB9>0,BC9>0,BD9<=0,BE9>0,BC9>=BB9,BB9>=BE9)=TRUE,1,0) -> 0 | BM9: =IF(AND(BB9>0,BC9>0,BD9>0,BE9<=0,BC9>=BB9,BB9>=BD9)=TRUE,1,0) -> 0 | BN9: =IF(AND(BB9>0,BC9>0,BD9>0,BE9<=0,BC9>=BD9,BD9>=BB9)=TRUE,1,0) -> 0 | BO9: =IF(AND(BB9>0,BC9<=0,BD9>0,BE9>0,BD9>=BB9,BB9>=BE9)=TRUE,1,0) -> 0 | BP9: =IF(AND(BB9>0,BC9>0,BD9<=0,BE9<=0,BB9>=BC9)=TRUE,1,0) -> 0 | BQ9: =IF(AND(BB9>0,BC9>0,BD9>0,BE9<=0,BB9>=BC9,BC9>=BD9)=TRUE,1,0) -> 0 | BR9: =IF(AND(BB9>0,BC9<=0,BD9>0,BE9<=0,BB9>=BD9)=TRUE,1,0) -> 0 | BS9: =IF(AND(BB9<=0,BC9>0,BD9>0,BE9>0,BE9>=BC9,BC9>=BD9)=TRUE,1,0) -> 0 | BT9: =IF(AND(BB9<=0,BC9>0,BD9>0,BE9>0,BE9>=BD9,BD9>=BC9)=TRUE,1,0) -> 0 | BU9: =IF(AND(BB9<=0,BC9>0,BD9>0,BE9>0,BC9>=BD9,BC9>=BE9)=TRUE,1,0) -> 0 | BV9: =IF(AND(BB9<=0,BC9<=0,BD9>0,BE9<=0)=TRUE,1,0) -> 0 | BW9: =IF(AND(BB9<=0,BC9<=0,BD9>0,BE9>0,BE9>=BD9)=TRUE,1,0) -> 0 | BX9: =IF(AND(BB9<=0,BC9<=0,BD9>0,BE9>0,BD9>=BE9)=TRUE,1,0) -> 0 | BY9: =IF(AND(BC9<=0,BD9<=0,BB9>0,BE9>0,BB9>=BE9)=TRUE,1,0) -> 0 | BZ9: =IF(AND(BB9>0,BC9>0,BE9>0,BD9<=0,BB9>=BC9,BC9>=BE9)=TRUE,1,0) -> 0 | CA9: =IF(AND(BB9>0,BD9>0,BC9>0,BE9<=0,BB9>=BD9,BD9>=BC9)=TRUE,1,0) -> 0 | CB9: =IF(AND(BB9>0,BD9>0,BE9>0,BC9<=0,BB9>=BD9,BD9>=BE9)=TRUE,1,0) -> 0 | CC9: =IF(AND(BB9>0,BC9>0,BE9>0,BD9<=0,BB9>=BE9,BE9>=BC9)=TRUE,1,0) -> 0 | CD9: =IF(AND(BB9>0,BD9>0,BE9>0,BC9<=0,BB9>=BE9,BE9>=BD9)=TRUE,1,0) -> 0 | CE9: =IF(AND(BB9<=0,BD9<=0,BE9<=0,BC9>0)=TRUE,1,0) -> 0 | CF9: =IF(AND(BC9>0,BD9>0,BB9<=0,BE9<=0,BC9>=BD9)=TRUE,1,0) -> 0 | CG9: =IF(AND(BC9>0,BE9>0,BB9<=0,BD9<=0,BC9>=BE9)=TRUE,1,0) -> 0 | CH9: =IF(AND(BB9>0,BC9>0,BE9>0,BD9<=0,BC9>=BE9,BE9>=BB9)=TRUE,1,0) -> 0 | CI9: =IF(AND(BB9<=0,BC9>0,BD9>0,BE9>0,BC9>=BE9,BE9>=BD9)=TRUE,1,0) -> 0 | CJ9: =IF(AND(BB9>0,BC9<=0,BD9>0,BE9<=0,BD9>=BB9)=TRUE,1,0) -> 0 | CK9: =IF(AND(BC9>0,BD9>0,BB9<=0,BE9<=0,BD9>=BC9)=TRUE,1,0) -> 0 | CL9: =IF(AND(BB9>0,BC9>0,BD9>0,BE9<=0,BD9>=BB9,BB9>=BC9)=TRUE,1,0) -> 0 | CM9: =IF(AND(BB9>0,BC9>0,BD9>0,BE9<=0,BD9>=BC9,BC9>=BB9)=TRUE,1,0) -> 0 | CN9: =IF(AND(BC9>0,BD9>0,BE9>0,BB9<=0,BD9>=BC9,BC9>=BE9)=TRUE,1,0) -> 0 | CO9: =IF(AND(BB9>0,BC9<=0,BD9>0,BE9>0,BD9>=BE9,BE9>=BB9)=TRUE,1,0) -> 0 | CP9: =IF(AND(BC9>0,BD9>0,BE9>0,BB9<=0,BD9>=BE9,BE9>=BC9)=TRUE,1,0) -> 0 | CQ9: =IF(AND(BC9>0,BE9>0,BB9<=0,BD9<=0,BE9>=BC9)=TRUE,1,0) -> 0 | CR9: =IF(AND(BB9>0,BC9>0,BE9>0,BD9<=0,BE9>=BB9,BB9>=BC9)=TRUE,1,0) -> 0 | CS9: =IF(AND(BB9>0,BD9>0,BE9>0,BC9<=0,BE9>=BB9,BB9>=BD9)=TRUE,1,0) -> 0 | CT9: =IF(AND(BB9>0,BC9>0,BE9>0,BD9<=0,BE9>=BC9,BC9>=BB9)=TRUE,1,0) -> 0 | CU9: =IF(AND(BB9>0,BD9>0,BE9>0,BC9<=0,BE9>=BD9,BD9>=BB9)=TRUE,1,0) -> 0 | CY9: =MATCH(1,BH9:CW9,0) -> 4
G10: 1 | H10: =IF(Input!C6="","",Input!E15+Input!J15+Input!O15) -> 7 | I10: =IF(Input!C6="","",Input!E16+Input!J16+Input!O16) -> 10 | J10: =IF(Input!C6="","",Input!E17+Input!J17+Input!O17) -> 1 | K10: =IF(Input!C6="","",Input!E18+Input!J18+Input!O18) -> 2 | L10: =IF(Input!C6="","",Input!E19+Input!J19+Input!O19) -> 4 | M10: =IF(SUM(H10:L10)=24,24,"ERR") -> 24 | BB10: D | BC10: I | BD10: S | BE10: C
G11: 2 | H11: =IF(Input!C6="","",Input!F15+Input!K15+Input!P15) -> 4 | I11: =IF(Input!C6="","",Input!F16+Input!K16+Input!P16) -> 0 | J11: =IF(Input!C6="","",Input!F17+Input!K17+Input!P17) -> 7 | K11: =IF(Input!C6="","",Input!F18+Input!K18+Input!P18) -> 7 | L11: =IF(Input!C6="","",Input!F19+Input!K19+Input!P19) -> 6 | M11: =IF(SUM(H11:L11)=24,24,"ERR") -> 24 | BA11: 3 | BB11: =VLOOKUP(H12,Sheet3!$B$28:$F$72,2) -> 1 | BC11: =VLOOKUP(I12,Sheet3!$B$28:$F$72,3) -> 7 | BD11: =VLOOKUP(J12,Sheet3!$B$28:$F$72,4) -> -3 | BE11: =VLOOKUP(K12,Sheet3!$B$28:$F$72,5) -> -2.5 | BH11: =IF(AND(BB11<=0,BC11<=0,BD11<=0,BE11>0)=TRUE,1,0) -> 0 | BI11: =IF(AND(BB11>0,BC11<=0,BD11<=0,BE11<=0)=TRUE,1,0) -> 0 | BJ11: =IF(AND(BB11>0,BC11<=0,BD11<=0,BE11>0,BE11>=BB11)=TRUE,1,0) -> 0 | BK11: =IF(AND(BB11>0,BC11>0,BD11<=0,BE11<=0,BC11>=BB11)=TRUE,1,0) -> 1 | BL11: =IF(AND(BB11>0,BC11>0,BD11<=0,BE11>0,BC11>=BB11,BB11>=BE11)=TRUE,1,0) -> 0 | BM11: =IF(AND(BB11>0,BC11>0,BD11>0,BE11<=0,BC11>=BB11,BB11>=BD11)=TRUE,1,0) -> 0 | BN11: =IF(AND(BB11>0,BC11>0,BD11>0,BE11<=0,BC11>=BD11,BD11>=BB11)=TRUE,1,0) -> 0 | BO11: =IF(AND(BB11>0,BC11<=0,BD11>0,BE11>0,BD11>=BB11,BB11>=BE11)=TRUE,1,0) -> 0 | BP11: =IF(AND(BB11>0,BC11>0,BD11<=0,BE11<=0,BB11>=BC11)=TRUE,1,0) -> 0 | BQ11: =IF(AND(BB11>0,BC11>0,BD11>0,BE11<=0,BB11>=BC11,BC11>=BD11)=TRUE,1,0) -> 0 | BR11: =IF(AND(BB11>0,BC11<=0,BD11>0,BE11<=0,BB11>=BD11)=TRUE,1,0) -> 0 | BS11: =IF(AND(BB11<=0,BC11>0,BD11>0,BE11>0,BE11>=BC11,BC11>=BD11)=TRUE,1,0) -> 0 | BT11: =IF(AND(BB11<=0,BC11>0,BD11>0,BE11>0,BE11>=BD11,BD11>=BC11)=TRUE,1,0) -> 0 | BU11: =IF(AND(BB11<=0,BC11>0,BD11>0,BE11>0,BC11>=BD11,BC11>=BE11)=TRUE,1,0) -> 0 | BV11: =IF(AND(BB11<=0,BC11<=0,BD11>0,BE11<=0)=TRUE,1,0) -> 0 | BW11: =IF(AND(BB11<=0,BC11<=0,BD11>0,BE11>0,BE11>=BD11)=TRUE,1,0) -> 0 | BX11: =IF(AND(BB11<=0,BC11<=0,BD11>0,BE11>0,BD11>=BE11)=TRUE,1,0) -> 0 | BY11: =IF(AND(BC11<=0,BD11<=0,BB11>0,BE11>0,BB11>=BE11)=TRUE,1,0) -> 0 | BZ11: =IF(AND(BB11>0,BC11>0,BE11>0,BD11<=0,BB11>=BC11,BC11>=BE11)=TRUE,1,0) -> 0 | CA11: =IF(AND(BB11>0,BD11>0,BC11>0,BE11<=0,BB11>=BD11,BD11>=BC11)=TRUE,1,0) -> 0 | CB11: =IF(AND(BB11>0,BD11>0,BE11>0,BC11<=0,BB11>=BD11,BD11>=BE11)=TRUE,1,0) -> 0 | CC11: =IF(AND(BB11>0,BC11>0,BE11>0,BD11<=0,BB11>=BE11,BE11>=BC11)=TRUE,1,0) -> 0 | CD11: =IF(AND(BB11>0,BD11>0,BE11>0,BC11<=0,BB11>=BE11,BE11>=BD11)=TRUE,1,0) -> 0 | CE11: =IF(AND(BB11<=0,BD11<=0,BE11<=0,BC11>0)=TRUE,1,0) -> 0 | CF11: =IF(AND(BC11>0,BD11>0,BB11<=0,BE11<=0,BC11>=BD11)=TRUE,1,0) -> 0 | CG11: =IF(AND(BC11>0,BE11>0,BB11<=0,BD11<=0,BC11>=BE11)=TRUE,1,0) -> 0 | CH11: =IF(AND(BB11>0,BC11>0,BE11>0,BD11<=0,BC11>=BE11,BE11>=BB11)=TRUE,1,0) -> 0 | CI11: =IF(AND(BB11<=0,BC11>0,BD11>0,BE11>0,BC11>=BE11,BE11>=BD11)=TRUE,1,0) -> 0 | CJ11: =IF(AND(BB11>0,BC11<=0,BD11>0,BE11<=0,BD11>=BB11)=TRUE,1,0) -> 0 | CK11: =IF(AND(BC11>0,BD11>0,BB11<=0,BE11<=0,BD11>=BC11)=TRUE,1,0) -> 0 | CL11: =IF(AND(BB11>0,BC11>0,BD11>0,BE11<=0,BD11>=BB11,BB11>=BC11)=TRUE,1,0) -> 0 | CM11: =IF(AND(BB11>0,BC11>0,BD11>0,BE11<=0,BD11>=BC11,BC11>=BB11)=TRUE,1,0) -> 0 | CN11: =IF(AND(BC11>0,BD11>0,BE11>0,BB11<=0,BD11>=BC11,BC11>=BE11)=TRUE,1,0) -> 0 | CO11: =IF(AND(BB11>0,BC11<=0,BD11>0,BE11>0,BD11>=BE11,BE11>=BB11)=TRUE,1,0) -> 0 | CP11: =IF(AND(BC11>0,BD11>0,BE11>0,BB11<=0,BD11>=BE11,BE11>=BC11)=TRUE,1,0) -> 0 | CQ11: =IF(AND(BC11>0,BE11>0,BB11<=0,BD11<=0,BE11>=BC11)=TRUE,1,0) -> 0 | CR11: =IF(AND(BB11>0,BC11>0,BE11>0,BD11<=0,BE11>=BB11,BB11>=BC11)=TRUE,1,0) -> 0 | CS11: =IF(AND(BB11>0,BD11>0,BE11>0,BC11<=0,BE11>=BB11,BB11>=BD11)=TRUE,1,0) -> 0 | CT11: =IF(AND(BB11>0,BC11>0,BE11>0,BD11<=0,BE11>=BC11,BC11>=BB11)=TRUE,1,0) -> 0 | CU11: =IF(AND(BB11>0,BD11>0,BE11>0,BC11<=0,BE11>=BD11,BD11>=BB11)=TRUE,1,0) -> 0 | CY11: =MATCH(1,BH11:CW11,0) -> 4
G12: 3 | H12: =H10-H11 -> 3 | I12: =I10-I11 -> 10 | J12: =J10-J11 -> -6 | K12: =K10-K11 -> -5
B42: Gambaran Karakter
B43: Kepribadian Saat di Publik | L43: Kepribadian Saat Mendapat Tekanan
B44: =HLOOKUP($CY$7,Def!$B$2:$AQ$16,3) -> NEGOTIATOR | L44: =HLOOKUP($CY$9,Def!$B$2:$AQ$16,3) -> NEGOTIATOR
B45: =HLOOKUP($CY$7,Def!$B$2:$AQ$16,4) -> Suka Bergaul | L45: =HLOOKUP($CY$9,Def!$B$2:$AQ$16,4) -> Suka Bergaul
B46: =HLOOKUP($CY$7,Def!$B$2:$AQ$16,5) -> Anti Rutin | L46: =HLOOKUP($CY$9,Def!$B$2:$AQ$16,5) -> Anti Rutin
B47: =HLOOKUP($CY$7,Def!$B$2:$AQ$16,6) -> Aktif | L47: =HLOOKUP($CY$9,Def!$B$2:$AQ$16,6) -> Aktif
B48: =HLOOKUP($CY$7,Def!$B$2:$AQ$16,7) -> Terlalu Percaya Diri | L48: =HLOOKUP($CY$9,Def!$B$2:$AQ$16,7) -> Terlalu Percaya Diri
B49: =HLOOKUP($CY$7,Def!$B$2:$AQ$16,8) -> Agresif | L49: =HLOOKUP($CY$9,Def!$B$2:$AQ$16,8) -> Agresif
B50: =HLOOKUP($CY$7,Def!$B$2:$AQ$16,9) -> Optimis | L50: =HLOOKUP($CY$9,Def!$B$2:$AQ$16,9) -> Optimis
B51: =HLOOKUP($CY$7,Def!$B$2:$AQ$16,10) -> Kurang Detail | L51: =HLOOKUP($CY$9,Def!$B$2:$AQ$16,10) -> Kurang Detail
B52: =HLOOKUP($CY$7,Def!$B$2:$AQ$16,11) -> Result Oriented | L52: =HLOOKUP($CY$9,Def!$B$2:$AQ$16,11) -> Result Oriented
B53: =HLOOKUP($CY$7,Def!$B$2:$AQ$16,12) | L53: =HLOOKUP($CY$9,Def!$B$2:$AQ$16,12)
B54: =HLOOKUP($CY$7,Def!$B$2:$AQ$16,13) | L54: =HLOOKUP($CY$9,Def!$B$2:$AQ$16,13)
B55: =HLOOKUP($CY$7,Def!$B$2:$AQ$16,14) | L55: =HLOOKUP($CY$9,Def!$B$2:$AQ$16,14)
B56: =HLOOKUP($CY$7,Def!$B$2:$AQ$16,15) | L56: =HLOOKUP($CY$9,Def!$B$2:$AQ$16,15)
B59: Kepribadian Asli / Sesungguhnya
B60: =HLOOKUP($CY$11,Def!$B$2:$AQ$16,3) -> NEGOTIATOR
B61: =HLOOKUP($CY$11,Def!$B$2:$AQ$16,4) -> Suka Bergaul
B62: =HLOOKUP($CY$11,Def!$B$2:$AQ$16,5) -> Anti Rutin
B63: =HLOOKUP($CY$11,Def!$B$2:$AQ$16,6) -> Aktif
B64: =HLOOKUP($CY$11,Def!$B$2:$AQ$16,7) -> Terlalu Percaya Diri
B65: =HLOOKUP($CY$11,Def!$B$2:$AQ$16,8) -> Agresif
B66: =HLOOKUP($CY$11,Def!$B$2:$AQ$16,9) -> Optimis
B67: =HLOOKUP($CY$11,Def!$B$2:$AQ$16,10) -> Kurang Detail
B68: =HLOOKUP($CY$11,Def!$B$2:$AQ$16,11) -> Result Oriented
B69: =HLOOKUP($CY$11,Def!$B$2:$AQ$16,12)
B70: =HLOOKUP($CY$11,Def!$B$2:$AQ$16,13)
B71: =HLOOKUP($CY$11,Def!$B$2:$AQ$16,14)
B72: =HLOOKUP($CY$11,Def!$B$2:$AQ$16,15)
...

Sheet Sheet3
C1: 1 | G1: 2
C2: D | D2: I | E2: S | F2: C | G2: D | H2: I | I2: S | J2: C
B3: 0 | C3: -6 | D3: -7 | E3: -5.7 | F3: -6 | G3: 7.5 | H3: 7 | I3: 7.5 | J3: 7.5
B4: 1 | C4: -5.3 | D4: -4.6 | E4: -4.3 | F4: -4.7 | G4: 6.5 | H4: 6 | I4: 7 | J4: 7
B5: 2 | C5: -4 | D5: -2.5 | E5: -3.5 | F5: -3.5 | G5: 4.3 | H5: 4 | I5: 6 | J5: 5.6
B6: 3 | C6: -2.5 | D6: -1.3 | E6: -1.5 | F6: -1.5 | G6: 2.5 | H6: 2.5 | I6: 4 | J6: 4
B7: 4 | C7: -1.7 | D7: 1 | E7: -0.7 | F7: 0.5 | G7: 1.5 | H7: 0.5 | I7: 2.5 | J7: 2.5
B8: 5 | C8: -1.3 | D8: 3 | E8: 0.5 | F8: 2 | G8: 0.5 | H8: 0 | I8: 1.5 | J8: 1.5
B9: 6 | C9: 0 | D9: 3.5 | E9: 1 | F9: 3 | G9: 0 | H9: -2 | I9: 0.5 | J9: 0.5
B10: 7 | C10: 0.5 | D10: 5.3 | E10: 2.5 | F10: 5.3 | G10: -1.3 | H10: -3.5 | I10: -1.3 | J10: 0
B11: 8 | C11: 1 | D11: 5.7 | E11: 3 | F11: 5.7 | G11: -1.5 | H11: -4.3 | I11: -2 | J11: -1.3
B12: 9 | C12: 2 | D12: 6 | E12: 4 | F12: 6 | G12: -2.5 | H12: -5.3 | I12: -3 | J12: -2.5
B13: 10 | C13: 3 | D13: 6.5 | E13: 4.6 | F13: 6.3 | G13: -3 | H13: -6 | I13: -4.3 | J13: -3.5
B14: 11 | C14: 3.5 | D14: 7 | E14: 5 | F14: 6.5 | G14: -3.5 | H14: -6.5 | I14: -5.3 | J14: -5.3
... B23: 20 | C23: 7.5 | D23: 8 | E23: 7.5 | F23: 8 | G23: -7.5 | H23: -8 | I23: -8 | J23: -8
C26: 3
C27: D | D27: I | E27: S | F27: C
B28: -22 | C28: -8 | D28: -8 | E28: -8 | F28: -7.5
B29: -21 | C29: -7.5 | D29: -8 | E29: -8 | F29: -7.3
B30: -20 | C30: -7 | D30: -8 | E30: -8 | F30: -7.3
B31: -19 | C31: -6.8 | D31: -8 | E31: -8 | F31: -7
B32: -18 | C32: -6.75 | D32: -7 | E32: -7.5 | F32: -6.7
B33: -17 | C33: -6.7 | D33: -6.7 | E33: -7.3 | F33: -6.7
B34: -16 | C34: -6.5 | D34: -6.7 | E34: -7.3 | F34: -6.7
B35: -15 | C35: -6.3 | D35: -6.7 | E35: -7 | F35: -6.5
B36: -14 | C36: -6.1 | D36: -6.7 | E36: -6.5 | F36: -6.3
B37: -13 | C37: -5.9 | D37: -6.7 | E37: -6.5 | F37: -6
B38: -12 | C38: -5.7 | D38: -6.7 | E38: -6.5 | F38: -5.85
B39: -11 | C39: -5.3 | D39: -6.7 | E39: -6.5 | F39: -5.85
... B55: 5 | C55: 1.5 | D55: 4.3 | E55: 4 | F55: 5.7
B56: 6 | C56: 2 | D56: 5 | F56: 6
B57: 7 | C57: 2.5 | D57: 5.5 | E57: 4.7 | F57: 6.3
B58: 8 | C58: 3.5 | D58: 6.5 | E58: 5 | F58: 6.5 | L58: 12
B59: 9 | C59: 4 | D59: 6.7 | E59: 5.5 | F59: 6.7 | L59: 250000
B60: 10 | C60: 4.7 | D60: 7 | E60: 6 | F60: 7 | L60: =L59*L58 -> 3000000
B61: 11 | C61: 4.85 | D61: 7.3 | E61: 6.2 | F61: 7.3
B62: 12 | C62: 5 | D62: 7.3 | E62: 6.3 | F62: 7.3
B63: 13 | C63: 5.5 | D63: 7.3 | E63: 6.5 | F63: 7.3
B64: 14 | C64: 6 | D64: 7.3 | E64: 6.7 | F64: 7.3
B65: 15 | C65: 6.3 | D65: 7.3 | E65: 7 | F65: 7.3
...

Sheet Sheet1
C1: 1 | G1: 2
C2: D | D2: I | E2: S | F2: C | G2: D | H2: I | I2: S | J2: C
B3: 0 | C3: -6 | D3: -7 | E3: -5.7 | F3: -6 | G3: 7.5 | H3: 7 | I3: 7.5 | J3: 7.5
B4: 1 | C4: -5.3 | D4: -4.6 | E4: -4.3 | F4: -4.7 | G4: 6.5 | H4: 6 | I4: 7 | J4: 7
B5: 2 | C5: -4 | D5: -2.5 | E5: -3.5 | F5: -3.5 | G5: 4.3 | H5: 4 | I5: 6 | J5: 5.6
B6: 3 | C6: -2.5 | D6: -1.3 | E6: -1.5 | F6: -1.5 | G6: 2.5 | H6: 2.5 | I6: 4 | J6: 4
B7: 4 | C7: -1.7 | D7: 1 | E7: -0.7 | F7: 0.5 | G7: 1.5 | H7: 0.5 | I7: 2.5 | J7: 2.5
B8: 5 | C8: -1.3 | D8: 3 | E8: 0.5 | F8: 2 | G8: 0.5 | H8: 0 | I8: 1.5 | J8: 1.5
B9: 6 | C9: 0 | D9: 3.5 | E9: 1 | F9: 3 | G9: 0 | H9: -2 | I9: 0.5 | J9: 0.5
B10: 7 | C10: 0.5 | D10: 5.3 | E10: 2.5 | F10: 5.3 | G10: -1.3 | H10: -3.5 | I10: -1.3 | J10: 0
B11: 8 | C11: 1 | D11: 5.7 | E11: 3 | F11: 5.7 | G11: -1.5 | H11: -4.3 | I11: -2 | J11: -1.3
B12: 9 | C12: 2 | D12: 6 | E12: 4 | F12: 6 | G12: -2.5 | H12: -5.3 | I12: -3 | J12: -2.5
B13: 10 | C13: 3 | D13: 6.5 | E13: 4.6 | F13: 6.3 | G13: -3 | H13: -6 | I13: -4.3 | J13: -3.5
B14: 11 | C14: 3.5 | D14: 7 | E14: 5 | F14: 6.5 | G14: -3.5 | H14: -6.5 | I14: -5.3 | J14: -5.3
... B23: 20 | C23: 7.5 | D23: 8 | E23: 7.5 | F23: 8 | G23: -7.5 | H23: -8 | I23: -8 | J23: -8
C26: 3
C27: D | D27: I | E27: S | F27: C
B28: -22 | C28: -8 | D28: -8 | E28: -8 | F28: -7.5
B29: -21 | C29: -7.5 | D29: -8 | E29: -8 | F29: -7.3
B30: -20 | C30: -7 | D30: -8 | E30: -8 | F30: -7.3
B31: -19 | C31: -6.8 | D31: -8 | E31: -8 | F31: -7
B32: -18 | C32: -6.75 | D32: -7 | E32: -7.5 | F32: -6.7
B33: -17 | C33: -6.7 | D33: -6.7 | E33: -7.3 | F33: -6.7
B34: -16 | C34: -6.5 | D34: -6.7 | E34: -7.3 | F34: -6.7
B35: -15 | C35: -6.3 | D35: -6.7 | E35: -7 | F35: -6.5
B36: -14 | C36: -6.1 | D36: -6.7 | E36: -6.5 | F36: -6.3
B37: -13 | C37: -5.9 | D37: -6.7 | E37: -6.5 | F37: -6
B38: -12 | C38: -5.7 | D38: -6.7 | E38: -6.5 | F38: -5.85
B39: -11 | C39: -5.3 | D39: -6.7 | E39: -6.5 | F39: -5.85
... B55: 5 | C55: 1.5 | D55: 4.3 | E55: 4 | F55: 5.7
B56: 6 | C56: 2 | D56: 5 | F56: 6
B57: 7 | C57: 2.5 | D57: 5.5 | E57: 4.7 | F57: 6.3
B58: 8 | C58: 3.5 | D58: 6.5 | E58: 5 | F58: 6.5
B59: 9 | C59: 4 | D59: 6.7 | E59: 5.5 | F59: 6.7
B60: 10 | C60: 4.7 | D60: 7 | E60: 6 | F60: 7
B61: 11 | C61: 4.85 | D61: 7.3 | E61: 6.2 | F61: 7.3
B62: 12 | C62: 5 | D62: 7.3 | E62: 6.3 | F62: 7.3
B63: 13 | C63: 5.5 | D63: 7.3 | E63: 6.5 | F63: 7.3
B64: 14 | C64: 6 | D64: 7.3 | E64: 6.7 | F64: 7.3
B65: 15 | C65: 6.3 | D65: 7.3 | E65: 7 | F65: 7.3
...

Sheet Sheet3 (2)
C1: 1 | G1: 2
C2: D | D2: I | E2: S | F2: C | G2: D | H2: I | I2: S | J2: C
B3: 0 | C3: -30 | D3: -36 | E3: -28 | F3: -30 | G3: 37 | H3: 35 | I3: 37 | J3: 37
B4: 1 | C4: -26 | D4: -24 | E4: -22 | F4: -24 | G4: 33 | H4: 30 | I4: 35 | J4: 35
B5: 2 | C5: -20 | D5: -13 | E5: -17 | F5: -17 | G5: 22 | H5: 19 | I5: 30 | J5: 28
B6: 3 | C6: -13 | D6: -6 | E6: -8 | F6: -8 | G6: 13 | H6: 13 | I6: 19 | J6: 19
B7: 4 | C7: -8 | D7: 5 | E7: -4 | F7: 3 | G7: 7 | H7: 3 | I7: 13 | J7: 12
B8: 5 | C8: -6 | D8: 15 | E8: 3 | F8: 10 | G8: 3 | H8: -2 | I8: 7 | J8: 7
B9: 6 | C9: -2 | D9: 17 | E9: 5 | F9: 15 | G9: -2 | H9: -10 | I9: 3 | J9: 3
B10: 7 | C10: 3 | D10: 26 | E10: 13 | F10: 26 | G10: -6 | H10: -17 | I10: -6 | J10: -2
B11: 8 | C11: 5 | D11: 28 | E11: 15 | F11: 28 | G11: -8 | H11: -22 | I11: -10 | J11: -6
B12: 9 | C12: 10 | D12: 30 | E12: 19 | F12: 30 | G12: -13 | H12: -26 | I12: -15 | J12: -12
B13: 10 | C13: 15 | D13: 33 | E13: 24 | F13: 31 | G13: -15 | H13: -30 | I13: -22 | J13: -17
B14: 11 | C14: 17 | D14: 35 | E14: 26 | F14: 33 | G14: -17 | H14: -33 | I14: -26 | J14: -26
... B23: 20 | C23: 37 | D23: 40 | E23: 37 | F23: 40 | G23: -37 | H23: -40 | I23: -40 | J23: -40
C26: 3
C27: D | D27: I | E27: S | F27: C
B28: -22 | C28: -37
B29: -21 | C29: -36
B30: -20 | C30: -35
B31: -19 | C31: -34
B32: -18 | C32: -34
B33: -17 | C33: -34
B34: -16 | C34: -33
B35: -15 | C35: -31
B36: -14 | C36: -30
B37: -13 | C37: -29
B38: -12 | C38: -28
B39: -11 | C39: -26
... B57: 7 | C57: 12
B58: 8 | C58: 16 | L58: 12
B59: 9 | C59: 18 | L59: 250000
B60: 10 | C60: 24 | L60: =L59*L58 -> 3000000
B61: 11 | C61: 25
B62: 12 | C62: 26
B63: 13 | C63: 28
B64: 14 | C64: 30
B65: 15 | C65: 31
B66: 16 | C66: 33
B67: 17 | C67: 34
...

Sheet Def
B2: 1 | C2: 2 | D2: 3 | E2: 4 | F2: 5 | G2: 6 | H2: 7 | I2: 8 | J2: 9 | K2: 10 | L2: 11 | M2: 12 | N2: 13 | O2: 14 | P2: 15 | Q2: 16 | R2: 17 | S2: 18 | T2: 19 | U2: 20 | V2: 21 | W2: 22 | X2: 23 | Y2: 24 | Z2: 25 | AA2: 26 | AB2: 27 | AC2: 28 | AD2: 29 | AE2: 30 | AF2: 31 | AG2: 32 | AH2: 33 | AI2: 34 | AJ2: 35 | AK2: 36 | AL2: 37 | AM2: 38 | AN2: 39 | AO2: 40
B3: C | C3: D | D3: D / C-D | E3: D / I-D | F3: D / I-D-C | G3: D / I-D-S | H3: D / I-S-D | I3: D / S-D-C / S-C-D | J3: D-I | K3: D-I-S | L3: D-S | M3: I / C-I-S | N3: I / C-S-I | O3: I-S-C / I-C-S | P3: S | Q3: S / C-S | R3: S-C | S3: D-C | T3: D-I-C | U3: D-S-I | V3: D-S-C | W3: D-C-I | X3: D-C-S | Y3: I | Z3: I-S | AA3: I-C | AB3: I-C-D | AC3: I-C-S | AD3: S-D | AE3: S-I | AF3: S-D-I | AG3: S-I-D | AH3: S-I-C | AI3: S-C-D | AJ3: S-C-I | AK3: C-I | AL3: C-D-I | AM3: C-D-S | AN3: C-I-D | AO3: C-S-D
B4: LOGICAL THINKER | C4: ESTABLISHER | D4: DESIGNER | E4: NEGOTIATOR | F4: CONFIDENT & DETERMINED | G4: REFORMER | H4: MOTIVATOR | I4: INQUIRER | J4: PENGAMBIL KEPUTUSAN | K4: DIRECTOR | L4: SELF-MOTIVATED | M4: MEDIATOR | N4: PRACTITIONER | O4: RESPONSIVE & THOUGHTFUL | P4: SPECIALIST | Q4: PERFECTIONIST | R4: PEACEMAKER, RESPECTFULL & ACCURATE | S4: CHALLENGER | T4: CHANCELLOR | U4: DIRECTOR | V4: Director | W4: CHALLENGER | X4: CHALLENGER | Y4: COMMUNICATOR | Z4: ADVISOR | AA4: ASSESSOR | AB4: ASSESSOR | AC4: RESPONSIVE & THOUGHTFUL | AD4: SELF-MOTIVATED | AE4: ADVISOR | AF4: DIRECTOR | AG4: ADVISOR | AH4: ADVOCATE | AI4: INQUIRER | AJ4: ADVOCATE | AK4: ASSESSOR | AL4: CHALLENGER | AM4: CONTEMPLATOR | AN4: ASSESSOR | AO4: PRECISIONIST
B5: Pendiam | C5: Individualis | D5: Sensitif | E5: Suka Bergaul | F5: Pandai Memilih Orang | G5: Mudah Bergaul | H5: Leader (Kelompok Kecil) | I5: Full Self Control | J5: Pekerja Keras | K5: Pengelola | L5: Objektif & Analitis | M5: Loyal | N5: Perfeksionis | O5: High Energy | P5: Stabil & Konsisten | Q5: Detail & Teliti | R5: Sulit Beradaptasi | S5: Seorang yang tekun | T5: Seorang yang ramah secara alami | U5: Seorang yang obyektif dan analitis | V5: Seorang yang obyektif dan analitis | W5: Seorang yang tekun | X5: Seorang yang tekun | Y5: Antusias | Z5: Hangat | AA5: Ramah | AB5: Analitis | AC5: High Energy | AD5: Objektif & Analitis | AE5: Hangat | AF5: Seorang yang obyektif dan analitis | AG5: Hangat | AH5: Stabil | AI5: Seorang yang baik | AJ5: Stabil | AK5: Analitis | AL5: Sangat berorientasi pada tugas | AM5: Berorientasi pada hal-hal detil | AN5: Analitis | AO5: Sistematis dan Prosedural
B6: Anti Kritik | C6: Ego Tinggi, Kurang Sensitif | D6: Kurang Cepat | E6: Anti Rutin | F6: Leader | G6: Leader | H6: Supporter | I6: Sabar | J6: Leader | K6: Enerjik | L6: Mandiri | M6: Tight Scheduled | N6: Quality Oriented | O6: Good Communication Skill | P6: Terkendali | Q6: Butuh Situasi Stabil | R6: Anti Kritik | S6: Sensitif terhadap permasalahan | T6: Menggabungkan kesenangan dengan pekerjaan | U6: Ingin terlibat dalam situasi | V6: Ingin terlibat dalam situasi | W6: Sensitif terhadap permasalahan | X6: Sensitif terhadap permasalahan | Y6: Percaya | Z6: Simpati | AA6: Suka berteman | AB6: Berwatak hati-hati | AC6: Good Communication Skill | AD6: Mandiri | AE6: Simpati dan Pengertian | AF6: Ingin terlibat dalam situasi | AG6: Simpati dan Pengertian | AH6: Ramah | AI6: Sangat berorientasi pada detil | AJ6: Ramah | AK6: Berwatak hati-hati | AL6: Sensitif terhadap permasalahan | AM6: Mempunyai standar tinggi untuk dirinya | AN6: Berwatak hati-hati | AO6: Teratur & memiliki perencanaan yang baik
B7: Perfeksionis | C7: Kurang Pertimbangan | D7: Anti Tekanan | E7: Aktif | F7: Good Interpersonal Skill | G7: Sadar Diri | H7: Sosialisasi Baik | I7: Penuh Pertimbangan | J7: Banyak Minat | K7: Kurang Detail | L7: Good Planner | M7: Curious | N7: Scheduled | O7: To The Point | P7: Nyaman di Belakang Layar | Q7: Sistematik & Prosedural | R7: Pendendam | S7: Mempunyai keputusan yang kuat | T7: Menyukai hubungan dengan sesama | U7: Ingin memberikan bantuan dan dukungan | V7: Ingin memberikan bantuan dan dukungan | W7: Mempunyai keputusan yang kuat | X7: Mempunyai keputusan yang kuat | Y7: Optimis | Z7: Tenang dalam situasi sosial | AA7: Nyaman walapun dengan orang asing | AB7: Ramah pada saat merasa nyaman | AC7: To The Point | AD7: Good planner | AE7: Tenang dalam situasi sosial | AF7: Ingin memberikan bantuan dan dukungan | AG7: Tenang dalam situasi sosial | AH7: Detail ketika situasi membutuhkan | AI7: Sangat teliti dalam penyelesaian tugas | AJ7: Detail ketika situasi membutuhkan | AK7: Ramah pada saat merasa nyaman | AL7: Lebih mempedulikan tugas daripada orang | AM7: Logis dan analitis | AN7: Ramah pada saat merasa nyaman | AO7: Teliti
B8: Cenderung Santai | C8: Efektif | D8: Terlalu Mandiri | E8: Terlalu Percaya Diri | F8: Dominan | G8: Butuh Pujian & Penghargaan | H8: Butuh Ketegasan | I8: Good Interpersonal | J8: Dingin / Task Oriented | K8: Mudah Bosan | L8: Komitmen thd Target | M8: Sensitif | N8: Anti Kejutan | O8: Sensitif | P8: Sabar | Q8: Menghindari Konflik | R8: Sukar Berubah | S8: Kreatif dalam memecahkan masalah | T8: Menikmati interaksi dengan sesama | U8: Termotivasi oleh target pribadi | V8: Termotivasi oleh target pribadi | W8: Kreatif dalam memecahkan masalah | X8: Kreatif dalam memecahkan masalah | Y8: Persuasif | Z8: Pendengar yang baik | AA8: Mudah mengembangkan hubungan baru | AB8: Sangat biasa dengan orang asing | AC8: Sensitif | AD8: Komitmen terhadap target | AE8: Pendengar yang baik | AF8: Termotivasi oleh target pribadi | AG8: Pendengar yang baik | AH8: Cenderung individualis | AI8: Sangat berhati-hati | AJ8: Cenderung individualis | AK8: Sangat biasa dengan orang asing | AL8: Kukuh/keras | AM8: Ingin berbuat yang terbaik | AN8: Sangat biasa dengan orang asing | AO8: Fokus pada detil
B9: Detail | C9: High Motivation | D9: Kurang Percaya Orang Lain | E9: Agresif | F9: Agresif | G9: Cepat Percaya Orang | H9: Butuh Pujian & Penghargaan | I9: Selektif | J9: Kurang Pergaulan | K9: Agresif | L9: Menghindari Konflik | M9: Good Communication Skill | N9: Good Interpersonal Skill | O9: Banyak Bicara | P9: Loyal | Q9: Anti Kritik | R9: Detail | S9: Memiliki reaksi yang cepat | T9: Dapat mengerjakan hal-hal detil | U9: Berorientasi terhadap pekerjaannya | V9: Berorientasi terhadap pekerjaannya | W9: Memiliki reaksi yang cepat | X9: Memiliki reaksi yang cepat | Y9: Bicara aktif | Z9: Demonstratif | AA9: Dapat mengendalikan diri | AB9: Mudah mengembangkan hubungan baru | AC9: Banyak Bicara | AD9: Menghindari konflik | AE9: Demonstratif | AF9: Berorientasi terhadap pekerjaannya | AG9: Demonstratif | AH9: Teguh pendirian | AI9: Penuh pertimbangan | AJ9: Teguh pendirian | AK9: Mudah mengembangkan hubungan baru | AL9: Dingin | AM9: Selalu berpikir ada ruang untuk kemajuan | AN9: Mudah mengembangkan hubungan baru | AO9: Bijaksana
B10: Empati | C10: Bersemangat Tinggi | D10: Anti Kritik | E10: Optimis | F10: Perfeksionis | G10: Mudah Simpati & Empati | H10: Kurang Detail | I10: Lambat Adaptasi | J10: Kontrol Emosi Kurang | K10: Arogan | M10: Good Analitical Think | N10: Terlalu Detail | O10: Need Recognation | P10: Sulit Adaptasi | Q10: Lambat Memutuskan | R10: Empati | S10: Mampu mencari solusi permasalahan | T10: Ingin melakukan segala sesuatu dengan tepat | U10: Menyukai hubungan dengan sesama | V10: Menyukai hubungan dengan sesama | W10: Mampu mencari solusi permasalahan | X10: Mampu mencari solusi permasalahan | Y10: Impulsif | Z10: Tidak memaksakan idenya pada orang lain | AA10: Sangat sosial | AB10: Dapat mengendalikan diri | AC10: Need Recognation | AD10: Ingin terlibat dalam situasi | AE10: Tidak memaksakan idenya pada orang lain | AF10: Menyukai hubungan dengan sesama | AG10: Tidak memaksakan idenya pada orang lain | AH10: Menyukai hubungan dengan orang | AI10: Lambat adaptasi | AJ10: Menyukai hubungan dengan orang | AK10: Dapat mengendalikan diri | AL10: Tidak berperasaan | AM10: Kompetitif | AN10: Dapat mengendalikan diri | AO10: Diplomatis
B11: Rapi | C11: Percaya Diri, cenderung Nekat | D11: Dingin | E11: Kurang Detail | F11: Good Communication Skill | G11: Motivator | H11: Agak Kaku | I11: Inisiatif kurang | J11: Suka Tantangan | K11: Kurang Focus | M11: Good Interpersonal Skill | N11: Sistematis | O11: Need Socialism | P11: Process Oriented | Q11: Sulit Adaptasi | R11: Memikirkan Dampak ke Orang Lain | S11: Banyak memberikan ide-ide. | T11: Menilai orang dan tugas secara hati-hati | U11: Mempunyai determinasi yang kuat | V11: Mempunyai determinasi yang kuat | W11: Banyak memberikan ide-ide. | X11: Banyak memberikan ide-ide. | Y11: Emosional | Z11: Kurang tegas dalam memberi perintah | AA11: Cenderung perfeksionis alamiah | AB11: Peduli dan ramah | AC11: Need Socialism | AD11: Ingin memberikan bantuan dan dukungan | AE11: Kurang tegas dalam memberi perintah | AF11: Mempunyai determinasi yang kuat | AG11: Kurang tegas dalam memberi perintah | AH11: Mendukung pihak yang lemah | AI11: Kaku dan keras kepala | AJ11: Mendukung pihak yang lemah | AK11: Peduli dan ramah | AL11: Menjaga jarak | AM11: Ingin menghasilkan mutu yang terbaik | AN11: Peduli dan ramah | AO11: Jarang menentang rekan kerjanya
B12: Organized | C12: Kreatif | D12: Kreatif | E12: Result Oriented | F12: Aktif | G12: Optimis & Positif | I12: Result Oriented | J12: Cepat Bosan | M12: Cepat Beradaptasi | N12: Kaku / Tidak fleksibel | O12: Anti thd Kritik | P12: Teguh | Q12: Pendendam | R12: Terlalu Mendalam dalam Berpikir | S12: Usaha yang keras pada ketepatan | T12: Sering melalaikan perencanaan yang seksama | U12: Karakternya tenang | V12: Karakternya tenang | W12: Usaha yang keras pada ketepatan | X12: Usaha yang keras pada ketepatan | Y12: Ramah | Z12: Menerima kritik | AA12: Mempromosikan tugas-tugas orang lain | AB12: Memusatkan perhatian pada penyelesaian tugas | AC12: Anti thd Kritik | AD12: Termotivasi oleh target pribadi | AE12: Menerima kritik | AF12: Karakternya tenang | AG12: Menerima kritik | AH12: Ingin diterima sebagai anggota tim | AJ12: Ingin diterima sebagai anggota tim | AK12: Memusatkan perhatian pada penyelesaian tugas | AL12: Membuat keputusan berdasarkan fakta | AM12: Mampu mencapai sasarannya | AN12: Memusatkan perhatian pada penyelesaian tugas | AO12: Ia sangat berhati-hati
B13: Kaku pada Metode & Prosedur | C13: Terlalu Dominan | D13: Result Oriented | F13: Need Recognition n Reward | G13: Anti Aturan | I13: Kaku dan Keras Kepala | J13: Anti Aturan | M13: Anti Kritik | N13: Monoton | O13: Terlalu banyak bersosialisasi | P13: Need for Peace | Q13: Anti Perubahan | R13: Concern ke Data dan Fakta | S13: Cenderung perfeksionis | T13: Mudah beralih kepada proyek-proyek baru | U13: Stabil dan daya tahannya tinggi | V13: Stabil dan daya tahannya tinggi | W13: Cenderung perfeksionis | X13: Cenderung perfeksionis | Y13: Inspirasional | Z13: Toleran dan sabar | AB13: Perfeksionis secara alami | AC13: Terlalu banyak bersosialisasi | AD13: Stabil | AE13: Toleran dan sabar | AF13: Stabil dan daya tahannya tinggi | AG13: Toleran dan sabar | AH13: Ingin orang lain menyukainya | AJ13: Ingin orang lain menyukainya | AK13: Perfeksionis secara alami | AL13: Pendiam | AM13: Sangat memusatkan perhatian pada tugas | AN13: Perfeksionis secara alami | AO13: Mengharapkan akurasi dan standard tinggi
C14: Agresif | D14: Suka Tantangan | F14: Kurang Peduli pada Aturan | G14: Kurang Detail | I14: Good Service | J14: Kurang Detail | M14: Not Leader | O14: Leadership kurang | P14: Anti Perubahan | R14: Introvert | U14: Ulet dalam memulai pekerjaan | V14: Ulet dalam memulai pekerjaan | Z14: Penjaga damai | AB14: Mengisolasi dirinya jika diperlukan | AC14: Leadership kurang | AD14: Tekun | AE14: Penjaga damai | AF14: Ulet dalam memulai pekerjaan | AG14: Penjaga damai | AH14: Sulit membuat keputusan | AJ14: Sulit membuat keputusan | AK14: Mengisolasi dirinya jika diperlukan | AL14: Tidak mudah percaya | AM14: Mantap dan dapat diandalkan | AN14: Mengisolasi dirinya jika diperlukan | AO14: Menginginkan adanya petunjuk standard
C15: Terlalu Dinamis | F15: Terburu-buru | G15: Terlalu Selektif | I15: Kurang dlm hal Managerial | J15: Kurang Peduli Wewenang | M15: Work/Play Conflict | O15: Kurang Fokus | P15: Sulit Menentukan Prioritas | R15: Loyal | U15: Berusaha keras mencapai sasarannya | V15: Berusaha keras mencapai sasarannya | AB15: Mudah diramalkan | AC15: Kurang Fokus | AF15: Berusaha keras mencapai sasarannya | AH15: Moderat | AJ15: Moderat | AK15: Mudah diramalkan | AN15: Mudah diramalkan | AO15: Tidak menginginkan perubahan mendadak
C16: Penuh Ambisi | J16: Argumentatif | O16: Anti Deadline | U16: Mandiri dan cermat | V16: Mandiri dan cermat | AB16: Berorientasi pada kualitas | AC16: Anti Deadline | AF16: Mandiri dan cermat | AH16: Cermat dan dapat diandalkan | AJ16: Cermat dan dapat diandalkan | AK16: Berorientasi pada kualitas | AN16: Berorientasi pada kualitas
